<mujoco model="pendulum_arm">
  <option gravity="0 0 -9.81" timestep="0.01"/>

  <worldbody>
    <!-- Base cố định -->
    <body name="base" pos="0 0 0" euler="0 0 0">
      <geom type="box" size="0.1 0.1 0.05" rgba="0.3 0.3 0.3 1" mass="10"/>

      <!-- Thanh rod gắn vào base -->
      <body name="rod" pos="0 0 0">
        <!-- Khớp bản lề cho phép quay quanh trục y -->
        <joint name="hinge" type="hinge" axis="0 1 0" pos="0 0 0" range="-90 90" damping="0.1" limited="true"/>
        <!-- Hình dạng thanh rod -->
        <geom type="capsule" fromto="0 0 0 0 0 -0.5" size="0.02" rgba="0.8 0.4 0.4 1" density="1000"/>
      </body>
    </body>
  </worldbody>
</mujoco>
